{
 "cells": [
  {
   "cell_type": "code",
   "execution_count": 1,
   "id": "142fc9e5",
   "metadata": {},
   "outputs": [
    {
     "name": "stderr",
     "output_type": "stream",
     "text": [
      "2022-01-13 20:29:06.656236: W tensorflow/stream_executor/platform/default/dso_loader.cc:64] Could not load dynamic library 'libcudart.so.11.0'; dlerror: libcudart.so.11.0: cannot open shared object file: No such file or directory\n",
      "2022-01-13 20:29:06.656254: I tensorflow/stream_executor/cuda/cudart_stub.cc:29] Ignore above cudart dlerror if you do not have a GPU set up on your machine.\n"
     ]
    }
   ],
   "source": [
    "import numpy as np\n",
    "import tensorflow as tf\n",
    "from tensorflow import keras\n",
    "from sklearn.model_selection import train_test_split\n",
    "\n",
    "(x_train, y_train), (x_test, y_test) = tf.keras.datasets.mnist.load_data()"
   ]
  },
  {
   "cell_type": "code",
   "execution_count": 4,
   "id": "ec31f636",
   "metadata": {},
   "outputs": [
    {
     "data": {
      "text/plain": [
       "(60000, 28, 28)"
      ]
     },
     "execution_count": 4,
     "metadata": {},
     "output_type": "execute_result"
    }
   ],
   "source": [
    "x_train.shape"
   ]
  },
  {
   "cell_type": "code",
   "execution_count": 3,
   "id": "07d4b97f",
   "metadata": {},
   "outputs": [
    {
     "data": {
      "text/plain": [
       "5"
      ]
     },
     "execution_count": 3,
     "metadata": {},
     "output_type": "execute_result"
    }
   ],
   "source": [
    "y_train[0]"
   ]
  },
  {
   "cell_type": "code",
   "execution_count": 6,
   "id": "b5b9e173",
   "metadata": {},
   "outputs": [
    {
     "name": "stdout",
     "output_type": "stream",
     "text": [
      "Epoch 1/100\n"
     ]
    },
    {
     "ename": "ValueError",
     "evalue": "in user code:\n\n    File \"/home/shantu/anaconda3/envs/ml/lib/python3.7/site-packages/keras/engine/training.py\", line 878, in train_function  *\n        return step_function(self, iterator)\n    File \"/home/shantu/anaconda3/envs/ml/lib/python3.7/site-packages/keras/engine/training.py\", line 867, in step_function  **\n        outputs = model.distribute_strategy.run(run_step, args=(data,))\n    File \"/home/shantu/anaconda3/envs/ml/lib/python3.7/site-packages/keras/engine/training.py\", line 860, in run_step  **\n        outputs = model.train_step(data)\n    File \"/home/shantu/anaconda3/envs/ml/lib/python3.7/site-packages/keras/engine/training.py\", line 808, in train_step\n        y_pred = self(x, training=True)\n    File \"/home/shantu/anaconda3/envs/ml/lib/python3.7/site-packages/keras/utils/traceback_utils.py\", line 67, in error_handler\n        raise e.with_traceback(filtered_tb) from None\n    File \"/home/shantu/anaconda3/envs/ml/lib/python3.7/site-packages/keras/engine/input_spec.py\", line 263, in assert_input_compatibility\n        raise ValueError(f'Input {input_index} of layer \"{layer_name}\" is '\n\n    ValueError: Input 0 of layer \"sequential_1\" is incompatible with the layer: expected shape=(None, 240, 1), found shape=(32, 28, 28)\n",
     "output_type": "error",
     "traceback": [
      "\u001b[0;31m---------------------------------------------------------------------------\u001b[0m",
      "\u001b[0;31mValueError\u001b[0m                                Traceback (most recent call last)",
      "\u001b[0;32m/tmp/ipykernel_298985/140313987.py\u001b[0m in \u001b[0;36m<module>\u001b[0;34m\u001b[0m\n\u001b[1;32m      7\u001b[0m \u001b[0mmodel\u001b[0m\u001b[0;34m.\u001b[0m\u001b[0mcompile\u001b[0m\u001b[0;34m(\u001b[0m\u001b[0moptimizer\u001b[0m \u001b[0;34m=\u001b[0m \u001b[0;34m'adam'\u001b[0m\u001b[0;34m,\u001b[0m \u001b[0mloss\u001b[0m\u001b[0;34m=\u001b[0m\u001b[0;34m'categorical_crossentropy'\u001b[0m\u001b[0;34m,\u001b[0m \u001b[0mmetrics\u001b[0m \u001b[0;34m=\u001b[0m \u001b[0;34m[\u001b[0m\u001b[0;34m'accuracy'\u001b[0m\u001b[0;34m]\u001b[0m\u001b[0;34m)\u001b[0m\u001b[0;34m\u001b[0m\u001b[0;34m\u001b[0m\u001b[0m\n\u001b[1;32m      8\u001b[0m \u001b[0;34m\u001b[0m\u001b[0m\n\u001b[0;32m----> 9\u001b[0;31m \u001b[0mmodel\u001b[0m\u001b[0;34m.\u001b[0m\u001b[0mfit\u001b[0m\u001b[0;34m(\u001b[0m\u001b[0mx_train\u001b[0m\u001b[0;34m,\u001b[0m \u001b[0my_train\u001b[0m\u001b[0;34m,\u001b[0m \u001b[0mepochs\u001b[0m \u001b[0;34m=\u001b[0m \u001b[0;36m100\u001b[0m\u001b[0;34m)\u001b[0m\u001b[0;34m\u001b[0m\u001b[0;34m\u001b[0m\u001b[0m\n\u001b[0m",
      "\u001b[0;32m~/anaconda3/envs/ml/lib/python3.7/site-packages/keras/utils/traceback_utils.py\u001b[0m in \u001b[0;36merror_handler\u001b[0;34m(*args, **kwargs)\u001b[0m\n\u001b[1;32m     65\u001b[0m     \u001b[0;32mexcept\u001b[0m \u001b[0mException\u001b[0m \u001b[0;32mas\u001b[0m \u001b[0me\u001b[0m\u001b[0;34m:\u001b[0m  \u001b[0;31m# pylint: disable=broad-except\u001b[0m\u001b[0;34m\u001b[0m\u001b[0;34m\u001b[0m\u001b[0m\n\u001b[1;32m     66\u001b[0m       \u001b[0mfiltered_tb\u001b[0m \u001b[0;34m=\u001b[0m \u001b[0m_process_traceback_frames\u001b[0m\u001b[0;34m(\u001b[0m\u001b[0me\u001b[0m\u001b[0;34m.\u001b[0m\u001b[0m__traceback__\u001b[0m\u001b[0;34m)\u001b[0m\u001b[0;34m\u001b[0m\u001b[0;34m\u001b[0m\u001b[0m\n\u001b[0;32m---> 67\u001b[0;31m       \u001b[0;32mraise\u001b[0m \u001b[0me\u001b[0m\u001b[0;34m.\u001b[0m\u001b[0mwith_traceback\u001b[0m\u001b[0;34m(\u001b[0m\u001b[0mfiltered_tb\u001b[0m\u001b[0;34m)\u001b[0m \u001b[0;32mfrom\u001b[0m \u001b[0;32mNone\u001b[0m\u001b[0;34m\u001b[0m\u001b[0;34m\u001b[0m\u001b[0m\n\u001b[0m\u001b[1;32m     68\u001b[0m     \u001b[0;32mfinally\u001b[0m\u001b[0;34m:\u001b[0m\u001b[0;34m\u001b[0m\u001b[0;34m\u001b[0m\u001b[0m\n\u001b[1;32m     69\u001b[0m       \u001b[0;32mdel\u001b[0m \u001b[0mfiltered_tb\u001b[0m\u001b[0;34m\u001b[0m\u001b[0;34m\u001b[0m\u001b[0m\n",
      "\u001b[0;32m~/anaconda3/envs/ml/lib/python3.7/site-packages/tensorflow/python/framework/func_graph.py\u001b[0m in \u001b[0;36mautograph_handler\u001b[0;34m(*args, **kwargs)\u001b[0m\n\u001b[1;32m   1127\u001b[0m           \u001b[0;32mexcept\u001b[0m \u001b[0mException\u001b[0m \u001b[0;32mas\u001b[0m \u001b[0me\u001b[0m\u001b[0;34m:\u001b[0m  \u001b[0;31m# pylint:disable=broad-except\u001b[0m\u001b[0;34m\u001b[0m\u001b[0;34m\u001b[0m\u001b[0m\n\u001b[1;32m   1128\u001b[0m             \u001b[0;32mif\u001b[0m \u001b[0mhasattr\u001b[0m\u001b[0;34m(\u001b[0m\u001b[0me\u001b[0m\u001b[0;34m,\u001b[0m \u001b[0;34m\"ag_error_metadata\"\u001b[0m\u001b[0;34m)\u001b[0m\u001b[0;34m:\u001b[0m\u001b[0;34m\u001b[0m\u001b[0;34m\u001b[0m\u001b[0m\n\u001b[0;32m-> 1129\u001b[0;31m               \u001b[0;32mraise\u001b[0m \u001b[0me\u001b[0m\u001b[0;34m.\u001b[0m\u001b[0mag_error_metadata\u001b[0m\u001b[0;34m.\u001b[0m\u001b[0mto_exception\u001b[0m\u001b[0;34m(\u001b[0m\u001b[0me\u001b[0m\u001b[0;34m)\u001b[0m\u001b[0;34m\u001b[0m\u001b[0;34m\u001b[0m\u001b[0m\n\u001b[0m\u001b[1;32m   1130\u001b[0m             \u001b[0;32melse\u001b[0m\u001b[0;34m:\u001b[0m\u001b[0;34m\u001b[0m\u001b[0;34m\u001b[0m\u001b[0m\n\u001b[1;32m   1131\u001b[0m               \u001b[0;32mraise\u001b[0m\u001b[0;34m\u001b[0m\u001b[0;34m\u001b[0m\u001b[0m\n",
      "\u001b[0;31mValueError\u001b[0m: in user code:\n\n    File \"/home/shantu/anaconda3/envs/ml/lib/python3.7/site-packages/keras/engine/training.py\", line 878, in train_function  *\n        return step_function(self, iterator)\n    File \"/home/shantu/anaconda3/envs/ml/lib/python3.7/site-packages/keras/engine/training.py\", line 867, in step_function  **\n        outputs = model.distribute_strategy.run(run_step, args=(data,))\n    File \"/home/shantu/anaconda3/envs/ml/lib/python3.7/site-packages/keras/engine/training.py\", line 860, in run_step  **\n        outputs = model.train_step(data)\n    File \"/home/shantu/anaconda3/envs/ml/lib/python3.7/site-packages/keras/engine/training.py\", line 808, in train_step\n        y_pred = self(x, training=True)\n    File \"/home/shantu/anaconda3/envs/ml/lib/python3.7/site-packages/keras/utils/traceback_utils.py\", line 67, in error_handler\n        raise e.with_traceback(filtered_tb) from None\n    File \"/home/shantu/anaconda3/envs/ml/lib/python3.7/site-packages/keras/engine/input_spec.py\", line 263, in assert_input_compatibility\n        raise ValueError(f'Input {input_index} of layer \"{layer_name}\" is '\n\n    ValueError: Input 0 of layer \"sequential_1\" is incompatible with the layer: expected shape=(None, 240, 1), found shape=(32, 28, 28)\n"
     ]
    }
   ],
   "source": [
    "model = tf.keras.models.Sequential([\n",
    "    tf.keras.layers.Flatten(input_shape = (28,28)), \n",
    "    tf.keras.layers.Dense(128, activation = 'relu'),\n",
    "    tf.keras.layers.Dense(10, activation = 'softmax')\n",
    "])\n",
    "\n",
    "model.compile(optimizer = 'adam', loss='categorical_crossentropy', metrics = ['accuracy'])\n",
    "\n",
    "model.fit(x_train, y_train, epochs = 100)"
   ]
  },
  {
   "cell_type": "code",
   "execution_count": null,
   "id": "86897ec4",
   "metadata": {},
   "outputs": [],
   "source": []
  }
 ],
 "metadata": {
  "kernelspec": {
   "display_name": "Python 3 (ipykernel)",
   "language": "python",
   "name": "python3"
  },
  "language_info": {
   "codemirror_mode": {
    "name": "ipython",
    "version": 3
   },
   "file_extension": ".py",
   "mimetype": "text/x-python",
   "name": "python",
   "nbconvert_exporter": "python",
   "pygments_lexer": "ipython3",
   "version": "3.7.11"
  }
 },
 "nbformat": 4,
 "nbformat_minor": 5
}
